Workbook

Sheet 4th netflix_titles
A1: show_id | B1: type | C1: Title | D1: director | E1: cast | F1: country | G1: date_added | H1: release_year | I1: rating | J1: duration | K1: Duration_Number | L1: Duration_Type | M1: listed_in | N1: description
A2: s1 | B2: Movie | C2: =TRIM('4th netflix_titles'!$C2) -> Dick Johnson Is Dead | D2: =TRIM(C2) -> Kirsten Johnson | E2: =TRIM(D2) -> Not Available | F2: =TRIM(E2) -> United States | G2: September 25, 2021 | H2: 2020 | I2: PG-13 | J2: 90 min | K2: =LEFT(J2,FIND(" ",J2)-1) -> 90 | L2: =RIGHT(J2,LEN(J2)-FIND(" ",J2)) -> min | M2: Documentaries | N2: =TRIM(M2) -> Documentaries
A3: s2 | B3: TV Show | C3: =TRIM('4th netflix_titles'!$C3) -> Blood & Water | D3: =TRIM(C3) -> UNKNOWN | E3: =TRIM(D3) -> Ama Qamata, Khosi Ngema, Gail Mabalane, Thabang Molaba, Dillon Windvogel, Natasha Thahane, Arno Greeff, Xolile Tshabalala, Getmore Sithole, Cindy Mahlangu, Ryle De Morny, Greteli Fincham, Sello Maake Ka-Ncube, Odwa Gwanya, Mekaila Mathys, Sandi Schultz, Duane Williams, Shamilla Miller, Patrick Mofokeng | F3: =TRIM(E3) -> South Africa | G3: September 24, 2021 | H3: 2021 | I3: TV-MA | J3: 2 Seasons | K3: =LEFT(J3,FIND(" ",J3)-1) -> 2 | L3: =RIGHT(J3,LEN(J3)-FIND(" ",J3)) -> Seasons | M3: International TV Shows, TV Dramas, TV Mysteries | N3: =TRIM(M3) -> International TV Shows, TV Dramas, TV Mysteries
A4: s3 | B4: TV Show | C4: =TRIM('4th netflix_titles'!$C4) -> Ganglands | D4: =TRIM(C4) -> Julien Leclercq | E4: =TRIM(D4) -> Sami Bouajila, Tracy Gotoas, Samuel Jouy, Nabiha Akkari, Sofia Lesaffre, Salim Kechiouche, Noureddine Farihi, Geert Van Rampelberg, Bakary Diombera | F4: =TRIM(E4) -> UNKNOWN | G4: September 24, 2021 | H4: 2021 | I4: TV-MA | J4: 1 Season | K4: =LEFT(J4,FIND(" ",J4)-1) -> 1 | L4: =RIGHT(J4,LEN(J4)-FIND(" ",J4)) -> Season | M4: Crime TV Shows, International TV Shows, TV Action & Adventure | N4: =TRIM(M4) -> Crime TV Shows, International TV Shows, TV Action & Adventure
A5: s4 | B5: TV Show | C5: =TRIM('4th netflix_titles'!$C5) -> Jailbirds New Orleans | D5: =TRIM(C5) -> UNKNOWN | E5: =TRIM(D5) -> Not Available | F5: =TRIM(E5) -> UNKNOWN | G5: September 24, 2021 | H5: 2021 | I5: TV-MA | J5: 1 Season | K5: =LEFT(J5,FIND(" ",J5)-1) -> 1 | L5: =RIGHT(J5,LEN(J5)-FIND(" ",J5)) -> Season | M5: Docuseries, Reality TV | N5: =TRIM(M5) -> Docuseries, Reality TV
A6: s5 | B6: TV Show | C6: =TRIM('4th netflix_titles'!$C6) -> Kota Factory | D6: =TRIM(C6) -> UNKNOWN | E6: =TRIM(D6) -> Mayur More, Jitendra Kumar, Ranjan Raj, Alam Khan, Ahsaas Channa, Revathi Pillai, Urvi Singh, Arun Kumar | F6: =TRIM(E6) -> India | G6: September 24, 2021 | H6: 2021 | I6: TV-MA | J6: 2 Seasons | K6: =LEFT(J6,FIND(" ",J6)-1) -> 2 | L6: =RIGHT(J6,LEN(J6)-FIND(" ",J6)) -> Seasons | M6: International TV Shows, Romantic TV Shows, TV Comedies | N6: =TRIM(M6) -> International TV Shows, Romantic TV Shows, TV Comedies
A7: s6 | B7: TV Show | C7: =TRIM('4th netflix_titles'!$C7) -> Midnight Mass | D7: =TRIM(C7) -> Mike Flanagan | E7: =TRIM(D7) -> Kate Siegel, Zach Gilford, Hamish Linklater, Henry Thomas, Kristin Lehman, Samantha Sloyan, Igby Rigney, Rahul Kohli, Annarah Cymone, Annabeth Gish, Alex Essoe, Rahul Abburi, Matt Biedel, Michael Trucco, Crystal Balint, Louis Oliver | F7: =TRIM(E7) -> UNKNOWN | G7: September 24, 2021 | H7: 2021 | I7: TV-MA | J7: 1 Season | K7: =LEFT(J7,FIND(" ",J7)-1) -> 1 | L7: =RIGHT(J7,LEN(J7)-FIND(" ",J7)) -> Season | M7: TV Dramas, TV Horror, TV Mysteries | N7: =TRIM(M7) -> TV Dramas, TV Horror, TV Mysteries
A8: s7 | B8: Movie | C8: =TRIM('4th netflix_titles'!$C8) -> My Little Pony: A New Generation | D8: =TRIM(C8) -> Robert Cullen, JosÃ© Luis Ucha | E8: =TRIM(D8) -> Vanessa Hudgens, Kimiko Glenn, James Marsden, Sofia Carson, Liza Koshy, Ken Jeong, Elizabeth Perkins, Jane Krakowski, Michael McKean, Phil LaMarr | F8: =TRIM(E8) -> UNKNOWN | G8: September 24, 2021 | H8: 2021 | I8: PG | J8: 91 min | K8: =LEFT(J8,FIND(" ",J8)-1) -> 91 | L8: =RIGHT(J8,LEN(J8)-FIND(" ",J8)) -> min | M8: Children & Family Movies | N8: =TRIM(M8) -> Children & Family Movies
A9: s8 | B9: Movie | C9: =TRIM('4th netflix_titles'!$C9) -> Sankofa | D9: =TRIM(C9) -> Haile Gerima | E9: =TRIM(D9) -> Kofi Ghanaba, Oyafunmike Ogunlano, Alexandra Duah, Nick Medley, Mutabaruka, Afemo Omilami, Reggie Carter, Mzuri | F9: =TRIM(E9) -> United States, Ghana, Burkina Faso, United Kingdom, Germany, Ethiopia | G9: September 24, 2021 | H9: 1993 | I9: TV-MA | J9: 125 min | K9: =LEFT(J9,FIND(" ",J9)-1) -> 125 | L9: =RIGHT(J9,LEN(J9)-FIND(" ",J9)) -> min | M9: Dramas, Independent Movies, International Movies | N9: =TRIM(M9) -> Dramas, Independent Movies, International Movies
A10: s9 | B10: TV Show | C10: =TRIM('4th netflix_titles'!$C10) -> The Great British Baking Show | D10: =TRIM(C10) -> Andy Devonshire | E10: =TRIM(D10) -> Mel Giedroyc, Sue Perkins, Mary Berry, Paul Hollywood | F10: =TRIM(E10) -> United Kingdom | G10: September 24, 2021 | H10: 2021 | I10: TV-14 | J10: 9 Seasons | K10: =LEFT(J10,FIND(" ",J10)-1) -> 9 | L10: =RIGHT(J10,LEN(J10)-FIND(" ",J10)) -> Seasons | M10: British TV Shows, Reality TV | N10: =TRIM(M10) -> British TV Shows, Reality TV
A11: s10 | B11: Movie | C11: =TRIM('4th netflix_titles'!$C11) -> The Starling | D11: =TRIM(C11) -> Theodore Melfi | E11: =TRIM(D11) -> Melissa McCarthy, Chris O'Dowd, Kevin Kline, Timothy Olyphant, Daveed Diggs, Skyler Gisondo, Laura Harrier, Rosalind Chao, Kimberly Quinn, Loretta Devine, Ravi Kapoor | F11: =TRIM(E11) -> United States | G11: September 24, 2021 | H11: 2021 | I11: PG-13 | J11: 104 min | K11: =LEFT(J11,FIND(" ",J11)-1) -> 104 | L11: =RIGHT(J11,LEN(J11)-FIND(" ",J11)) -> min | M11: Comedies, Dramas | N11: =TRIM(M11) -> Comedies, Dramas
A12: s11 | B12: TV Show | C12: =TRIM('4th netflix_titles'!$C12) -> Vendetta: Truth, Lies and The Mafia | D12: =TRIM(C12) -> UNKNOWN | E12: =TRIM(D12) -> Not Available | F12: =TRIM(E12) -> UNKNOWN | G12: September 24, 2021 | H12: 2021 | I12: TV-MA | J12: 1 Season | K12: =LEFT(J12,FIND(" ",J12)-1) -> 1 | L12: =RIGHT(J12,LEN(J12)-FIND(" ",J12)) -> Season | M12: Crime TV Shows, Docuseries, International TV Shows | N12: =TRIM(M12) -> Crime TV Shows, Docuseries, International TV Shows
A13: s12 | B13: TV Show | C13: =TRIM('4th netflix_titles'!$C13) -> Bangkok Breaking | D13: =TRIM(C13) -> Kongkiat Komesiri | E13: =TRIM(D13) -> Sukollawat Kanarot, Sushar Manaying, Pavarit Mongkolpisit, Sahajak Boonthanakit, Suthipongse Thatphithakkul, Bhasaworn Bawronkirati, Daweerit Chullasapya, Waratthaya Wongchayaporn, Kittiphoom Wongpentak, Abhicha Thanachanun, Nophand Boonyai, Kittipong Khamsat, Arisara Wongchalee, Jaytiya Naiwattanakul, Pantipa Arunwattanachai, Panupan Jantanawong, Kungtap Saelim, Phumphat Chartsuriyakiat, Issara Veranitinunt, Keerati Sivakuae, Panjai Sirisuwan, Supranee Charoenpol, Suda Chuenban, Visaka Banhansupavat, Pitchatorn Santinatornkul | F13: =TRIM(E13) -> UNKNOWN | G13: September 23, 2021 | H13: 2021 | I13: TV-MA | J13: 1 Season | K13: =LEFT(J13,FIND(" ",J13)-1) -> 1 | L13: =RIGHT(J13,LEN(J13)-FIND(" ",J13)) -> Season | M13: Crime TV Shows, International TV Shows, TV Action & Adventure | N13: =TRIM(M13) -> Crime TV Shows, International TV Shows, TV Action & Adventure
... A6067: s6066 | B6067: Movie | C6067: =TRIM('4th netflix_titles'!$C6067) -> A Wrinkle in Time | D6067: =TRIM(C6067) -> Ava DuVernay | E6067: =TRIM(D6067) -> Storm Reid, Oprah Winfrey, Reese Witherspoon, Mindy Kaling, Deric McCabe, Levi Miller, Chris Pine, Gugu Mbatha-Raw, Zach Galifianakis, Michael PeÃ±a, Bellamy Young, AndrÃ© Holland, Will McCormack, Rowan Blanchard, Daniel MacPherson | F6067: =TRIM(E6067) -> United States | G6067: September 25, 2018 | H6067: 2018 | I6067: PG | J6067: 110 min | K6067: =LEFT(J6067,FIND(" ",J6067)-1) -> 110 | L6067: =RIGHT(J6067,LEN(J6067)-FIND(" ",J6067)) -> min | M6067: Children & Family Movies | N6067: =TRIM(M6067) -> Children & Family Movies
A6068: s6067 | B6068: TV Show | C6068: =TRIM('4th netflix_titles'!$C6068) -> A Young Doctor's Notebook and Other Stories | D6068: =TRIM(C6068) -> UNKNOWN | E6068: =TRIM(D6068) -> Daniel Radcliffe, Jon Hamm, Adam Godley, Christopher Godwin, Rosie Cavaliero, Vicki Pepperdine, Margaret Clunie, Tim Steed, Shaun Pye | F6068: =TRIM(E6068) -> United Kingdom | H6068: 2013 | I6068: TV-MA | J6068: 2 Seasons | K6068: =LEFT(J6068,FIND(" ",J6068)-1) -> 2 | L6068: =RIGHT(J6068,LEN(J6068)-FIND(" ",J6068)) -> Seasons | M6068: British TV Shows, TV Comedies, TV Dramas | N6068: =TRIM(M6068) -> British TV Shows, TV Comedies, TV Dramas
A6069: s6068 | B6069: TV Show | C6069: =TRIM('4th netflix_titles'!$C6069) -> A.D. Kingdom and Empire | D6069: =TRIM(C6069) -> UNKNOWN | E6069: =TRIM(D6069) -> Juan Pablo Di Pace, Adam Levy, Chipo Chung, Babou Ceesay, Emmett Scanlan, Will Thorp, Richard Coyle, Vincent Regan, Greta Scacchi, James Callis, Joanne Whalley, Jodhi May, Chris Brazier, Fraser Ayres, JÃ³hannes Haukur JÃ³hannesson, Ken Bones, Kenneth Collard | F6069: =TRIM(E6069) -> United States | G6069: December 15, 2017 | H6069: 2015 | I6069: TV-14 | J6069: 1 Season | K6069: =LEFT(J6069,FIND(" ",J6069)-1) -> 1 | L6069: =RIGHT(J6069,LEN(J6069)-FIND(" ",J6069)) -> Season | M6069: TV Dramas | N6069: =TRIM(M6069) -> TV Dramas
A6070: s6069 | B6070: Movie | C6070: =TRIM('4th netflix_titles'!$C6070) -> A.M.I. | D6070: =TRIM(C6070) -> Rusty Nixon | E6070: =TRIM(D6070) -> Debs Howard, Philip Granger, Sam Robert Muik, Havana Guppy, Bonnie Hay, Veronica Hampson, Lori Triolo, Andrew Coghlan, Laura Mitchell, Elinet Louicius | F6070: =TRIM(E6070) -> Canada | G6070: October 1, 2020 | H6070: 2019 | I6070: TV-MA | J6070: 77 min | K6070: =LEFT(J6070,FIND(" ",J6070)-1) -> 77 | L6070: =RIGHT(J6070,LEN(J6070)-FIND(" ",J6070)) -> min | M6070: Horror Movies | N6070: =TRIM(M6070) -> Horror Movies
A6071: s6070 | B6071: Movie | C6071: =TRIM('4th netflix_titles'!$C6071) -> A.X.L. | D6071: =TRIM(C6071) -> Oliver Daly | E6071: =TRIM(D6071) -> Alex Neustaedter, Becky G., Alex MacNicoll, Dominic Rains, Thomas Jane, Lou Taylor Pucci, Patricia De Leon, Niko Guardado, Ted McGinley, Marie-FranÃ§oise Theodore, Eric Etebari, Dorian Kingi | F6071: =TRIM(E6071) -> United States | G6071: March 20, 2019 | H6071: 2018 | I6071: PG | J6071: 99 min | K6071: =LEFT(J6071,FIND(" ",J6071)-1) -> 99 | L6071: =RIGHT(J6071,LEN(J6071)-FIND(" ",J6071)) -> min | M6071: Action & Adventure, Children & Family Movies, Independent Movies | N6071: =TRIM(M6071) -> Action & Adventure, Children & Family Movies, Independent Movies
A6072: s6071 | B6072: Movie | C6072: =TRIM('4th netflix_titles'!$C6072) -> AÅŸk TesadÃ¼fleri Sever | D6072: =TRIM(C6072) -> Ã–mer Faruk Sorak | E6072: =TRIM(D6072) -> Mehmet GÃ¼nsÃ¼r, BelÃ§im Bilgin, Ayda Aksel, Altan Erkekli, Sebnem SÃ¶nmez, HÃ¼seyin Avni Danyal, Berna Konur, Ãœmit BÃ¼lent DinÃ§er | F6072: =TRIM(E6072) -> Turkey | G6072: April 4, 2018 | H6072: 2011 | I6072: TV-MA | J6072: 122 min | K6072: =LEFT(J6072,FIND(" ",J6072)-1) -> 122 | L6072: =RIGHT(J6072,LEN(J6072)-FIND(" ",J6072)) -> min | M6072: Dramas, International Movies, Romantic Movies | N6072: =TRIM(M6072) -> Dramas, International Movies, Romantic Movies
A6073: s6072 | B6073: Movie | C6073: =TRIM('4th netflix_titles'!$C6073) -> Aadu 2 | D6073: =TRIM(C6073) -> Midhun Manuel Thomas | E6073: =TRIM(D6073) -> Jayasurya, Vinayakan, Sunny Wayne, Vijay Babu, Saiju Kurup, Vineeth Mohan, Unni Rajan P. Dev, Dharmajan Bolgatty, Indrans | F6073: =TRIM(E6073) -> India | G6073: May 15, 2018 | H6073: 2017 | I6073: TV-MA | J6073: 150 min | K6073: =LEFT(J6073,FIND(" ",J6073)-1) -> 150 | L6073: =RIGHT(J6073,LEN(J6073)-FIND(" ",J6073)) -> min | M6073: Comedies, International Movies | N6073: =TRIM(M6073) -> Comedies, International Movies
A6074: s6073 | B6074: Movie | C6074: =TRIM('4th netflix_titles'!$C6074) -> Aajcha Divas Majha | D6074: =TRIM(C6074) -> Chandrakant Kulkarni | E6074: =TRIM(D6074) -> Sachin Khedekar, Ashwini Bhave, Mahesh Manjrekar, Hrishikesh Joshi, Satish Alekar, Sunil Tawde, Pushkar Shrotri, Anand Ingle | F6074: =TRIM(E6074) -> India | G6074: January 1, 2018 | H6074: 2013 | I6074: TV-PG | J6074: 126 min | K6074: =LEFT(J6074,FIND(" ",J6074)-1) -> 126 | L6074: =RIGHT(J6074,LEN(J6074)-FIND(" ",J6074)) -> min | M6074: Comedies, Dramas, International Movies | N6074: =TRIM(M6074) -> Comedies, Dramas, International Movies
A6075: s6074 | B6075: Movie | C6075: =TRIM('4th netflix_titles'!$C6075) -> Aarakshan | D6075: =TRIM(C6075) -> Prakash Jha | E6075: =TRIM(D6075) -> Amitabh Bachchan, Saif Ali Khan, Manoj Bajpayee, Deepika Padukone, Prateik, Tanvi Azmi, Saurabh Shukla, Darshan Jariwala, Yashpal Sharma, Mukesh Tiwari | F6075: =TRIM(E6075) -> India | G6075: December 31, 2019 | H6075: 2011 | I6075: TV-14 | J6075: 164 min | K6075: =LEFT(J6075,FIND(" ",J6075)-1) -> 164 | L6075: =RIGHT(J6075,LEN(J6075)-FIND(" ",J6075)) -> min | M6075: Dramas, International Movies | N6075: =TRIM(M6075) -> Dramas, International Movies
A6076: s6075 | B6076: Movie | C6076: =TRIM('4th netflix_titles'!$C6076) -> Aashayein | D6076: =TRIM(C6076) -> Nagesh Kukunoor | E6076: =TRIM(D6076) -> John Abraham, Sonal Sehgal, Prateeksha Lonkar, Girish Karnad, Farida Jalal, Ashwin Chitale, Anaitha Nair, Vikram Inamdar, Vipin Bhali, Poonam Chitale, Nagesh Kukunoor | F6076: =TRIM(E6076) -> India | G6076: October 22, 2017 | H6076: 2010 | I6076: TV-14 | J6076: 115 min | K6076: =LEFT(J6076,FIND(" ",J6076)-1) -> 115 | L6076: =RIGHT(J6076,LEN(J6076)-FIND(" ",J6076)) -> min | M6076: Dramas, International Movies | N6076: =TRIM(M6076) -> Dramas, International Movies
A6077: s6076 | B6077: Movie | C6077: =TRIM('4th netflix_titles'!$C6077) -> Aata Pita | D6077: =TRIM(C6077) -> Uttung Shelar | E6077: =TRIM(D6077) -> Sanjay Narvekar, Bharat Jadhav, Satish Phulekar, Ashwini Apte | F6077: =TRIM(E6077) -> India | G6077: January 1, 2018 | H6077: 2010 | I6077: TV-14 | J6077: 133 min | K6077: =LEFT(J6077,FIND(" ",J6077)-1) -> 133 | L6077: =RIGHT(J6077,LEN(J6077)-FIND(" ",J6077)) -> min | M6077: Comedies, Dramas, International Movies | N6077: =TRIM(M6077) -> Comedies, Dramas, International Movies
A6078: s6077 | B6078: Movie | C6078: =TRIM('4th netflix_titles'!$C6078) -> Abby Sen | D6078: =TRIM(C6078) -> Atanu Ghosh | E6078: =TRIM(D6078) -> Abir Chatterjee, Raima Sen, Arunima Ghosh, Priyanka Sarkar, Sujan Mukherjee, Kanchan Mullick, Biswanath Basu, Bhaswar Chatterjee, Swagata Basu, Tuhin Mitra, Paran Banerjee, Kharaj Mukherjee, Chiranjit | F6078: =TRIM(E6078) -> India | G6078: May 1, 2017 | H6078: 2015 | I6078: TV-PG | J6078: 127 min | K6078: =LEFT(J6078,FIND(" ",J6078)-1) -> 127 | L6078: =RIGHT(J6078,LEN(J6078)-FIND(" ",J6078)) -> min | M6078: Comedies, Dramas, International Movies | N6078: =TRIM(M6078) -> Comedies, Dramas, International Movies
A6079: s6078 | B6079: Movie | C6079: =TRIM('4th netflix_titles'!$C6079) -> Abdo Mota | D6079: =TRIM(C6079) -> UNKNOWN | E6079: =TRIM(D6079) -> Mohamed Ramadan | F6079: =TRIM(E6079) -> Egypt | G6079: April 19, 2019 | H6079: 2012 | I6079: TV-MA | J6079: 100 min | K6079: =LEFT(J6079,FIND(" ",J6079)-1) -> 100 | L6079: =RIGHT(J6079,LEN(J6079)-FIND(" ",J6079)) -> min | M6079: Action & Adventure, Dramas, International Movies | N6079: =TRIM(M6079) -> Action & Adventure, Dramas, International Movies
A6080: s6079 | B6080: Movie | C6080: =TRIM('4th netflix_titles'!$C6080) -> Abhinetri | D6080: =TRIM(C6080) -> A. L. Vijay | E6080: =TRIM(D6080) -> Tamannaah Bhatia, Prabhu Deva, Sonu Sood, Sapthagiri, Murli Sharma, R.V. Udhaykumar, Joy Mathew, Hema | F6080: =TRIM(E6080) -> India | G6080: May 1, 2018 | H6080: 2016 | I6080: TV-14 | J6080: 131 min | K6080: =LEFT(J6080,FIND(" ",J6080)-1) -> 131 | L6080: =RIGHT(J6080,LEN(J6080)-FIND(" ",J6080)) -> min | M6080: Comedies, International Movies, Sci-Fi & Fantasy | N6080: =TRIM(M6080) -> Comedies, International Movies, Sci-Fi & Fantasy
... A6175: s6174 | B6175: Movie | C6175: =TRIM('4th netflix_titles'!$C6175) -> Antariksha Ke Rakhwale | D6175: =TRIM(C6175) -> Anirban Majumder | E6175: =TRIM(D6175) -> Sonal Kaushal, Rupa Bhimani, Julie Tejwani, Sabina Malik, Jigna Bharadhwaj, Rajesh Kawa | F6175: =TRIM(E6175) -> UNKNOWN | G6175: June 18, 2019 | H6175: 2018 | I6175: TV-Y7 | J6175: 65 min | K6175: =LEFT(J6175,FIND(" ",J6175)-1) -> 65 | L6175: =RIGHT(J6175,LEN(J6175)-FIND(" ",J6175)) -> min | M6175: Children & Family Movies | N6175: =TRIM(M6175) -> Children & Family Movies
A6176: s6175 | B6176: TV Show | C6176: =TRIM('4th netflix_titles'!$C6176) -> Anthony Bourdain: Parts Unknown | D6176: =TRIM(C6176) -> UNKNOWN | E6176: =TRIM(D6176) -> Anthony Bourdain | F6176: =TRIM(E6176) -> United States | H6176: 2018 | I6176: TV-PG | J6176: 5 Seasons | K6176: =LEFT(J6176,FIND(" ",J6176)-1) -> 5 | L6176: =RIGHT(J6176,LEN(J6176)-FIND(" ",J6176)) -> Seasons | M6176: Docuseries | N6176: =TRIM(M6176) -> Docuseries
A6177: s6176 | B6177: Movie | C6177: =TRIM('4th netflix_titles'!$C6177) -> Antidote | D6177: =TRIM(C6177) -> Ken Barbet | E6177: =TRIM(D6177) -> Randy Couture, Chuck Zito, Wil Traval, Celeste Thornton, Rafael De La Fuente, Alyona Chekhova, Natali Yura, Thom Rivera | F6177: =TRIM(E6177) -> United States | G6177: April 14, 2019 | H6177: 2018 | I6177: TV-MA | J6177: 90 min | K6177: =LEFT(J6177,FIND(" ",J6177)-1) -> 90 | L6177: =RIGHT(J6177,LEN(J6177)-FIND(" ",J6177)) -> min | M6177: Action & Adventure, Horror Movies | N6177: =TRIM(M6177) -> Action & Adventure, Horror Movies
A6178: s6177 | B6178: Movie | C6178: =TRIM('4th netflix_titles'!$C6178) -> Anwar | D6178: =TRIM(C6178) -> Manish Jha | E6178: =TRIM(D6178) -> Siddharth Koirala, Nauheed Cyrusi, Manisha Koirala, Rajpal Yadav, Yashpal Sharma, Vijay Raaz, Hiten Tejwani, Sudhir Pandey, Sanjay Mishra, Lalit Tiwari | F6178: =TRIM(E6178) -> India | G6178: December 31, 2019 | H6178: 2007 | I6178: TV-14 | J6178: 134 min | K6178: =LEFT(J6178,FIND(" ",J6178)-1) -> 134 | L6178: =RIGHT(J6178,LEN(J6178)-FIND(" ",J6178)) -> min | M6178: Dramas, Independent Movies, International Movies | N6178: =TRIM(M6178) -> Dramas, Independent Movies, International Movies
A6179: s6178 | B6179: TV Show | C6179: =TRIM('4th netflix_titles'!$C6179) -> å¿è€…ãƒãƒƒãƒˆãƒªãã‚“ | D6179: =TRIM(C6179) -> UNKNOWN | E6179: =TRIM(D6179) -> Not Available | F6179: =TRIM(E6179) -> Japan | G6179: December 23, 2018 | H6179: 2012 | I6179: TV-Y7 | J6179: 2 Seasons | K6179: =LEFT(J6179,FIND(" ",J6179)-1) -> 2 | L6179: =RIGHT(J6179,LEN(J6179)-FIND(" ",J6179)) -> Seasons | M6179: Anime Series, Kids' TV | N6179: =TRIM(M6179) -> Anime Series, Kids' TV
A6180: s6179 | B6180: Movie | C6180: =TRIM('4th netflix_titles'!$C6180) -> Apache Warrior | D6180: =TRIM(C6180) -> David Salzberg, Christian Tureaud | E6180: =TRIM(D6180) -> Not Available | F6180: =TRIM(E6180) -> United States | G6180: November 1, 2019 | H6180: 2017 | I6180: TV-MA | J6180: 89 min | K6180: =LEFT(J6180,FIND(" ",J6180)-1) -> 89 | L6180: =RIGHT(J6180,LEN(J6180)-FIND(" ",J6180)) -> min | M6180: Documentaries | N6180: =TRIM(M6180) -> Documentaries
A6181: s6180 | B6181: Movie | C6181: =TRIM('4th netflix_titles'!$C6181) -> APEX: The Story of the Hypercar | D6181: =TRIM(C6181) -> J.F. Musial, Josh Vietze | E6181: =TRIM(D6181) -> Zachary Levi | F6181: =TRIM(E6181) -> United States | G6181: August 1, 2016 | H6181: 2016 | I6181: NR | J6181: 86 min | K6181: =LEFT(J6181,FIND(" ",J6181)-1) -> 86 | L6181: =RIGHT(J6181,LEN(J6181)-FIND(" ",J6181)) -> min | M6181: Documentaries | N6181: =TRIM(M6181) -> Documentaries
A6182: s6181 | B6182: Movie | C6182: =TRIM('4th netflix_titles'!$C6182) -> Apollo 18 | D6182: =TRIM(C6182) -> Gonzalo LÃ³pez-Gallego | E6182: =TRIM(D6182) -> Warren Christie, Lloyd Owen, Ryan Robbins, Michael Kopsa, Andrew Airlie | F6182: =TRIM(E6182) -> United States, Canada | G6182: March 9, 2019 | H6182: 2011 | I6182: PG-13 | J6182: 87 min | K6182: =LEFT(J6182,FIND(" ",J6182)-1) -> 87 | L6182: =RIGHT(J6182,LEN(J6182)-FIND(" ",J6182)) -> min | M6182: Horror Movies, Sci-Fi & Fantasy, Thrillers | N6182: =TRIM(M6182) -> Horror Movies, Sci-Fi & Fantasy, Thrillers
A6183: s6182 | B6183: Movie | C6183: =TRIM('4th netflix_titles'!$C6183) -> April and the Extraordinary World | D6183: =TRIM(C6183) -> Christian Desmares, Franck Ekinci | E6183: =TRIM(D6183) -> Angela Galuppo, Paul Giamatti, Susan Sarandon, Tony Hale, J.K. Simmons, Tony Robinow, Mark Camacho, Tod Fennell, Carlos Alazraqui, Kari Wahlgren | F6183: =TRIM(E6183) -> France, Canada, Belgium | G6183: October 1, 2017 | H6183: 2015 | I6183: PG | J6183: 107 min | K6183: =LEFT(J6183,FIND(" ",J6183)-1) -> 107 | L6183: =RIGHT(J6183,LEN(J6183)-FIND(" ",J6183)) -> min | M6183: Action & Adventure, Comedies, International Movies | N6183: =TRIM(M6183) -> Action & Adventure, Comedies, International Movies
A6184: s6183 | B6184: Movie | C6184: =TRIM('4th netflix_titles'!$C6184) -> Aram, Aram | D6184: =TRIM(C6184) -> Christopher Chambers | E6184: =TRIM(D6184) -> John Roohinian, Levon Sharafyan, Sevak Hakoyan, David Villada, Mike Ghader, Razmik Mansuryan, Lorita Meg, Amy Sanders, Alla Tumanian | F6184: =TRIM(E6184) -> United States | G6184: February 15, 2017 | H6184: 2015 | I6184: TV-14 | J6184: 79 min | K6184: =LEFT(J6184,FIND(" ",J6184)-1) -> 79 | L6184: =RIGHT(J6184,LEN(J6184)-FIND(" ",J6184)) -> min | M6184: Dramas, Independent Movies | N6184: =TRIM(M6184) -> Dramas, Independent Movies
A6185: s6184 | B6185: Movie | C6185: =TRIM('4th netflix_titles'!$C6185) -> Are We Done Yet? | D6185: =TRIM(C6185) -> Khaled El Halafawy | E6185: =TRIM(D6185) -> Ahmed Eid, Ayten Amer, Ahmed Fouad Selim, Mohsen Mansour | F6185: =TRIM(E6185) -> Egypt | G6185: August 1, 2019 | H6185: 2018 | I6185: TV-14 | J6185: 87 min | K6185: =LEFT(J6185,FIND(" ",J6185)-1) -> 87 | L6185: =RIGHT(J6185,LEN(J6185)-FIND(" ",J6185)) -> min | M6185: Comedies, Dramas, International Movies | N6185: =TRIM(M6185) -> Comedies, Dramas, International Movies
A6186: s6185 | B6186: Movie | C6186: =TRIM('4th netflix_titles'!$C6186) -> Arisan 2 | D6186: =TRIM(C6186) -> Nia Dinata | E6186: =TRIM(D6186) -> Surya Saputra, Cut Mini Theo, Tora Sudiro | F6186: =TRIM(E6186) -> Indonesia | G6186: September 15, 2018 | H6186: 2011 | I6186: TV-14 | J6186: 113 min | K6186: =LEFT(J6186,FIND(" ",J6186)-1) -> 113 | L6186: =RIGHT(J6186,LEN(J6186)-FIND(" ",J6186)) -> min | M6186: Comedies, Dramas, International Movies | N6186: =TRIM(M6186) -> Comedies, Dramas, International Movies
A6187: s6186 | B6187: Movie | C6187: =TRIM('4th netflix_titles'!$C6187) -> Arthur | D6187: =TRIM(C6187) -> Jason Winer | E6187: =TRIM(D6187) -> Russell Brand, Helen Mirren, Greta Gerwig, Jennifer Garner, Geraldine James, Luis GuzmÃ¡n, Nick Nolte, Christina Jacquelyn Calph, Murphy Guyer, JosÃ© RamÃ³n Rosario | F6187: =TRIM(E6187) -> United States | G6187: April 1, 2019 | H6187: 2011 | I6187: PG-13 | J6187: 110 min | K6187: =LEFT(J6187,FIND(" ",J6187)-1) -> 110 | L6187: =RIGHT(J6187,LEN(J6187)-FIND(" ",J6187)) -> min | M6187: Comedies, Romantic Movies | N6187: =TRIM(M6187) -> Comedies, Romantic Movies
...
